2021-10-11 11:20:43 WARNING (SyncWorker_1) [homeassistant.loader] We found a custom integration fullykiosk which has not been tested by Home Assistant. This component might cause stability problems, be sure to disable it if you experience issues with Home Assistant
2021-10-11 11:20:43 WARNING (SyncWorker_1) [homeassistant.loader] We found a custom integration hacs which has not been tested by Home Assistant. This component might cause stability problems, be sure to disable it if you experience issues with Home Assistant
2021-10-11 11:20:43 WARNING (SyncWorker_3) [homeassistant.loader] We found a custom integration knmi which has not been tested by Home Assistant. This component might cause stability problems, be sure to disable it if you experience issues with Home Assistant
2021-10-11 11:20:43 WARNING (SyncWorker_0) [homeassistant.loader] We found a custom integration browser_mod which has not been tested by Home Assistant. This component might cause stability problems, be sure to disable it if you experience issues with Home Assistant
2021-10-11 11:20:43 WARNING (SyncWorker_1) [homeassistant.loader] We found a custom integration climate_group which has not been tested by Home Assistant. This component might cause stability problems, be sure to disable it if you experience issues with Home Assistant
2021-10-11 11:20:43 WARNING (SyncWorker_2) [homeassistant.loader] We found a custom integration ovapi which has not been tested by Home Assistant. This component might cause stability problems, be sure to disable it if you experience issues with Home Assistant
2021-10-11 11:20:43 WARNING (SyncWorker_0) [homeassistant.loader] We found a custom integration readme which has not been tested by Home Assistant. This component might cause stability problems, be sure to disable it if you experience issues with Home Assistant
2021-10-11 11:20:43 WARNING (SyncWorker_6) [homeassistant.loader] We found a custom integration buienalarm which has not been tested by Home Assistant. This component might cause stability problems, be sure to disable it if you experience issues with Home Assistant
2021-10-11 11:20:43 WARNING (SyncWorker_4) [homeassistant.loader] We found a custom integration grocy which has not been tested by Home Assistant. This component might cause stability problems, be sure to disable it if you experience issues with Home Assistant
2021-10-11 11:20:43 WARNING (SyncWorker_2) [homeassistant.loader] We found a custom integration monitor_docker which has not been tested by Home Assistant. This component might cause stability problems, be sure to disable it if you experience issues with Home Assistant
2021-10-11 11:20:43 WARNING (SyncWorker_1) [homeassistant.loader] We found a custom integration breaking_changes which has not been tested by Home Assistant. This component might cause stability problems, be sure to disable it if you experience issues with Home Assistant
2021-10-11 11:20:43 WARNING (SyncWorker_6) [homeassistant.loader] We found a custom integration adaptive_lighting which has not been tested by Home Assistant. This component might cause stability problems, be sure to disable it if you experience issues with Home Assistant
2021-10-11 11:20:43 WARNING (SyncWorker_7) [homeassistant.loader] We found a custom integration neerslag which has not been tested by Home Assistant. This component might cause stability problems, be sure to disable it if you experience issues with Home Assistant
2021-10-11 11:20:47 WARNING (MainThread) [homeassistant.components.ssdp] Failed to setup listener for 0.0.0.0: [Errno 98] Address in use
2021-10-11 11:20:48 WARNING (MainThread) [zigpy.zcl] Unknown cluster 61184
2021-10-11 11:20:48 WARNING (MainThread) [zigpy.zcl] Unknown cluster 61184
2021-10-11 11:20:49 ERROR (MainThread) [homeassistant.components.binary_sensor] grocy: Error on device update!
Traceback (most recent call last):
  File "/usr/src/homeassistant/homeassistant/helpers/entity_platform.py", line 431, in _async_add_entity
    await entity.async_device_update(warning=False)
  File "/usr/src/homeassistant/homeassistant/helpers/entity.py", line 618, in async_device_update
    await task
  File "/config/custom_components/grocy/entity.py", line 57, in async_update
    await self.coordinator.async_request_refresh()
  File "/usr/src/homeassistant/homeassistant/helpers/update_coordinator.py", line 141, in async_request_refresh
    await self._debounced_refresh.async_call()
  File "/usr/src/homeassistant/homeassistant/helpers/debounce.py", line 78, in async_call
    await task
  File "/usr/src/homeassistant/homeassistant/helpers/update_coordinator.py", line 165, in async_refresh
    await self._async_refresh(log_failures=True)
  File "/usr/src/homeassistant/homeassistant/helpers/update_coordinator.py", line 265, in _async_refresh
    update_callback()
  File "/usr/src/homeassistant/homeassistant/helpers/entity.py", line 456, in async_write_ha_state
    self._async_write_ha_state()
  File "/usr/src/homeassistant/homeassistant/helpers/entity.py", line 496, in _async_write_ha_state
    extra_state_attributes = self.device_state_attributes
  File "/config/custom_components/grocy/entity.py", line 142, in device_state_attributes
    return json.loads(json.dumps(data, cls=GrocyJSONEncoder))
  File "/usr/local/lib/python3.9/json/__init__.py", line 234, in dumps
    return cls(
  File "/usr/local/lib/python3.9/json/encoder.py", line 199, in encode
    chunks = self.iterencode(o, _one_shot=True)
  File "/usr/local/lib/python3.9/json/encoder.py", line 257, in iterencode
    return _iterencode(o, 0)
  File "/config/custom_components/grocy/json_encode.py", line 26, in default
    return json.JSONEncoder.default(self, o)
  File "/usr/local/lib/python3.9/json/encoder.py", line 179, in default
    raise TypeError(f'Object of type {o.__class__.__name__} '
TypeError: Object of type ProductBarcodeData is not JSON serializable
2021-10-11 11:20:55 ERROR (MainThread) [homeassistant.components.sensor] The buienradar platform for the sensor integration does not support platform setup. Please remove it from your config.
2021-10-11 11:20:55 ERROR (SyncWorker_11) [homeassistant.components.command_line] Command failed: /config/scripts/get_shopping_list.py
2021-10-11 11:20:55 WARNING (SyncWorker_11) [homeassistant.components.command_line.sensor] Empty reply found when expecting JSON data
2021-10-11 11:20:55 WARNING (MainThread) [homeassistant.components.zha.core.channels.base] [0xE27B:1:0x0b04]: async_initialize: all attempts have failed: [DeliveryError('[0xe27b:1:0x0b04]: Message send failure'), DeliveryError('[0xe27b:1:0x0b04]: Message send failure'), DeliveryError('[0xe27b:1:0x0b04]: Message send failure'), DeliveryError('[0xe27b:1:0x0b04]: Message send failure')]
2021-10-11 11:20:55 WARNING (MainThread) [homeassistant.components.zha.core.channels.base] [0xE27B:1:0x0702]: async_initialize: all attempts have failed: [DeliveryError('[0xe27b:1:0x0702]: Message send failure'), DeliveryError('[0xe27b:1:0x0702]: Message send failure'), DeliveryError('[0xe27b:1:0x0702]: Message send failure'), DeliveryError('[0xe27b:1:0x0702]: Message send failure')]
2021-10-11 11:20:59 ERROR (MainThread) [homeassistant.components.sensor] grocy: Error on device update!
Traceback (most recent call last):
  File "/usr/src/homeassistant/homeassistant/helpers/entity_platform.py", line 431, in _async_add_entity
    await entity.async_device_update(warning=False)
  File "/usr/src/homeassistant/homeassistant/helpers/entity.py", line 618, in async_device_update
    await task
  File "/config/custom_components/grocy/entity.py", line 57, in async_update
    await self.coordinator.async_request_refresh()
  File "/usr/src/homeassistant/homeassistant/helpers/update_coordinator.py", line 141, in async_request_refresh
    await self._debounced_refresh.async_call()
  File "/usr/src/homeassistant/homeassistant/helpers/debounce.py", line 78, in async_call
    await task
  File "/usr/src/homeassistant/homeassistant/helpers/update_coordinator.py", line 165, in async_refresh
    await self._async_refresh(log_failures=True)
  File "/usr/src/homeassistant/homeassistant/helpers/update_coordinator.py", line 265, in _async_refresh
    update_callback()
  File "/usr/src/homeassistant/homeassistant/helpers/entity.py", line 456, in async_write_ha_state
    self._async_write_ha_state()
  File "/usr/src/homeassistant/homeassistant/helpers/entity.py", line 496, in _async_write_ha_state
    extra_state_attributes = self.device_state_attributes
  File "/config/custom_components/grocy/entity.py", line 142, in device_state_attributes
    return json.loads(json.dumps(data, cls=GrocyJSONEncoder))
  File "/usr/local/lib/python3.9/json/__init__.py", line 234, in dumps
    return cls(
  File "/usr/local/lib/python3.9/json/encoder.py", line 199, in encode
    chunks = self.iterencode(o, _one_shot=True)
  File "/usr/local/lib/python3.9/json/encoder.py", line 257, in iterencode
    return _iterencode(o, 0)
  File "/config/custom_components/grocy/json_encode.py", line 26, in default
    return json.JSONEncoder.default(self, o)
  File "/usr/local/lib/python3.9/json/encoder.py", line 179, in default
    raise TypeError(f'Object of type {o.__class__.__name__} '
TypeError: Object of type ProductBarcodeData is not JSON serializable
2021-10-11 11:21:05 WARNING (MainThread) [homeassistant.components.sensor] Setup of sensor platform command_line is taking over 10 seconds.
2021-10-11 11:21:15 WARNING (MainThread) [homeassistant.helpers.template] Template warning: 'float' got invalid input 'unknown' when rendering template '{{ states('sensor.curtains_front')|float > 0 }}' but no default was specified. Currently 'float' will return '0', however this template will fail to render in Home Assistant core 2021.12
2021-10-11 11:21:15 WARNING (MainThread) [homeassistant.helpers.template] Template warning: 'float' got invalid input 'unknown' when rendering template '{{ states('sensor.curtains_front')|float > 0 }}' but no default was specified. Currently 'float' will return '0', however this template will fail to render in Home Assistant core 2021.12
2021-10-11 11:21:15 ERROR (MainThread) [homeassistant.helpers.template] Template variable error: list object has no element 6 when rendering '{{ state_attr('sensor.recipies', 'recepten')[states('input_number.recipe_id')|round].description.split('<li>')[6].split('<br />')[0]|replace('</li>','')}}'
2021-10-11 11:21:15 ERROR (MainThread) [homeassistant.helpers.event] Error while processing template: Template("{{ state_attr('sensor.recipies', 'recepten')[states('input_number.recipe_id')|round].description.split('<li>')[6].split('<br />')[0]|replace('</li>','')}}")
Traceback (most recent call last):
  File "/usr/src/homeassistant/homeassistant/helpers/template.py", line 397, in async_render
    render_result = _render_with_context(self.template, compiled, **kwargs)
  File "/usr/src/homeassistant/homeassistant/helpers/template.py", line 1604, in _render_with_context
    return template.render(**kwargs)
  File "/usr/local/lib/python3.9/site-packages/jinja2/environment.py", line 1304, in render
    self.environment.handle_exception()
  File "/usr/local/lib/python3.9/site-packages/jinja2/environment.py", line 925, in handle_exception
    raise rewrite_traceback_stack(source=source)
  File "<template>", line 1, in top-level template code
  File "/usr/local/lib/python3.9/site-packages/jinja2/sandbox.py", line 326, in getattr
    value = getattr(obj, attribute)
  File "/usr/src/homeassistant/homeassistant/helpers/template.py", line 1630, in _fail_with_undefined_error
    raise ex
  File "/usr/src/homeassistant/homeassistant/helpers/template.py", line 1621, in _fail_with_undefined_error
    return super()._fail_with_undefined_error(*args, **kwargs)
jinja2.exceptions.UndefinedError: list object has no element 6

The above exception was the direct cause of the following exception:

Traceback (most recent call last):
  File "/usr/src/homeassistant/homeassistant/helpers/template.py", line 513, in async_render_to_info
    render_info._result = self.async_render(variables, strict=strict, **kwargs)
  File "/usr/src/homeassistant/homeassistant/helpers/template.py", line 399, in async_render
    raise TemplateError(err) from err
homeassistant.exceptions.TemplateError: UndefinedError: list object has no element 6
2021-10-11 11:21:15 ERROR (MainThread) [homeassistant.helpers.template] Template variable error: list object has no element 6 when rendering '{{ state_attr('sensor.recipies', 'recepten')[states('input_number.recipe_id')|round].description.split('<li>')[6].split('<br />')[0]|replace('</li>','')}}'
2021-10-11 11:21:15 ERROR (MainThread) [homeassistant.components.template.template_entity] TemplateError('UndefinedError: list object has no element 6') while processing template 'Template("{{ state_attr('sensor.recipies', 'recepten')[states('input_number.recipe_id')|round].description.split('<li>')[6].split('<br />')[0]|replace('</li>','')}}")' for attribute 'step_6' in entity 'sensor.cooking'
2021-10-11 11:21:15 ERROR (MainThread) [homeassistant.helpers.event] Error while processing template: Template("{%- for i in state_attr('sensor.grocy_stock', 'products') %} {%- if i.id == 93 %} {{ i.available_amount | round }} {%- endif %} {%- endfor %}")
Traceback (most recent call last):
  File "/usr/src/homeassistant/homeassistant/helpers/template.py", line 397, in async_render
    render_result = _render_with_context(self.template, compiled, **kwargs)
  File "/usr/src/homeassistant/homeassistant/helpers/template.py", line 1604, in _render_with_context
    return template.render(**kwargs)
  File "/usr/local/lib/python3.9/site-packages/jinja2/environment.py", line 1304, in render
    self.environment.handle_exception()
  File "/usr/local/lib/python3.9/site-packages/jinja2/environment.py", line 925, in handle_exception
    raise rewrite_traceback_stack(source=source)
  File "<template>", line 1, in top-level template code
TypeError: 'NoneType' object is not iterable

The above exception was the direct cause of the following exception:

Traceback (most recent call last):
  File "/usr/src/homeassistant/homeassistant/helpers/template.py", line 513, in async_render_to_info
    render_info._result = self.async_render(variables, strict=strict, **kwargs)
  File "/usr/src/homeassistant/homeassistant/helpers/template.py", line 399, in async_render
    raise TemplateError(err) from err
homeassistant.exceptions.TemplateError: TypeError: 'NoneType' object is not iterable
2021-10-11 11:21:15 ERROR (MainThread) [homeassistant.components.template.template_entity] TemplateError('TypeError: 'NoneType' object is not iterable') while processing template 'Template("{%- for i in state_attr('sensor.grocy_stock', 'products') %} {%- if i.id == 93 %} {{ i.available_amount | round }} {%- endif %} {%- endfor %}")' for attribute '_attr_native_value' in entity 'sensor.kattenvoer'
2021-10-11 11:21:16 WARNING (MainThread) [homeassistant.helpers.template] Template warning: 'timestamp_local' got invalid input 'None' when rendering template '{{ (now().strftime("%s")| int + (5*60)) | timestamp_custom("%H:%M") == as_timestamp(state_attr('calendar.feyenoord', 'start_time')  | timestamp_local) | timestamp_custom("%H:%M") }}' but no default was specified. Currently 'timestamp_local' will return 'None', however this template will fail to render in Home Assistant core 2021.12
2021-10-11 11:21:16 WARNING (MainThread) [homeassistant.helpers.template] Template warning: 'as_timestamp' got invalid input 'None' when rendering template '{{ (now().strftime("%s")| int + (5*60)) | timestamp_custom("%H:%M") == as_timestamp(state_attr('calendar.feyenoord', 'start_time')  | timestamp_local) | timestamp_custom("%H:%M") }}' but no default was specified. Currently 'as_timestamp' will return 'None', however this template will fail to render in Home Assistant core 2021.12
2021-10-11 11:21:16 WARNING (MainThread) [homeassistant.helpers.template] Template warning: 'timestamp_custom' got invalid input 'None' when rendering template '{{ (now().strftime("%s")| int + (5*60)) | timestamp_custom("%H:%M") == as_timestamp(state_attr('calendar.feyenoord', 'start_time')  | timestamp_local) | timestamp_custom("%H:%M") }}' but no default was specified. Currently 'timestamp_custom' will return 'None', however this template will fail to render in Home Assistant core 2021.12
2021-10-11 11:21:16 WARNING (MainThread) [homeassistant.helpers.template] Template warning: 'timestamp_local' got invalid input 'None' when rendering template '{{ (now().strftime("%s")| int + (5*60)) | timestamp_custom("%H:%M") == as_timestamp(state_attr('calendar.feyenoord', 'start_time')  | timestamp_local) | timestamp_custom("%H:%M") }}' but no default was specified. Currently 'timestamp_local' will return 'None', however this template will fail to render in Home Assistant core 2021.12
2021-10-11 11:21:16 WARNING (MainThread) [homeassistant.helpers.template] Template warning: 'as_timestamp' got invalid input 'None' when rendering template '{{ (now().strftime("%s")| int + (5*60)) | timestamp_custom("%H:%M") == as_timestamp(state_attr('calendar.feyenoord', 'start_time')  | timestamp_local) | timestamp_custom("%H:%M") }}' but no default was specified. Currently 'as_timestamp' will return 'None', however this template will fail to render in Home Assistant core 2021.12
2021-10-11 11:21:16 WARNING (MainThread) [homeassistant.helpers.template] Template warning: 'timestamp_custom' got invalid input 'None' when rendering template '{{ (now().strftime("%s")| int + (5*60)) | timestamp_custom("%H:%M") == as_timestamp(state_attr('calendar.feyenoord', 'start_time')  | timestamp_local) | timestamp_custom("%H:%M") }}' but no default was specified. Currently 'timestamp_custom' will return 'None', however this template will fail to render in Home Assistant core 2021.12
2021-10-11 11:21:16 WARNING (MainThread) [homeassistant.helpers.template] Template warning: 'timestamp_local' got invalid input 'None' when rendering template '{{ (now().strftime("%s")| int + (30*60)) | timestamp_custom("%H:%M") == as_timestamp(state_attr('calendar.feyenoord', 'start_time') | timestamp_local) | timestamp_custom("%H:%M") }}' but no default was specified. Currently 'timestamp_local' will return 'None', however this template will fail to render in Home Assistant core 2021.12
2021-10-11 11:21:16 WARNING (MainThread) [homeassistant.helpers.template] Template warning: 'as_timestamp' got invalid input 'None' when rendering template '{{ (now().strftime("%s")| int + (30*60)) | timestamp_custom("%H:%M") == as_timestamp(state_attr('calendar.feyenoord', 'start_time') | timestamp_local) | timestamp_custom("%H:%M") }}' but no default was specified. Currently 'as_timestamp' will return 'None', however this template will fail to render in Home Assistant core 2021.12
2021-10-11 11:21:16 WARNING (MainThread) [homeassistant.helpers.template] Template warning: 'timestamp_custom' got invalid input 'None' when rendering template '{{ (now().strftime("%s")| int + (30*60)) | timestamp_custom("%H:%M") == as_timestamp(state_attr('calendar.feyenoord', 'start_time') | timestamp_local) | timestamp_custom("%H:%M") }}' but no default was specified. Currently 'timestamp_custom' will return 'None', however this template will fail to render in Home Assistant core 2021.12
2021-10-11 11:21:16 WARNING (MainThread) [homeassistant.helpers.template] Template warning: 'timestamp_local' got invalid input 'None' when rendering template '{{ (now().strftime("%s")| int + (30*60)) | timestamp_custom("%H:%M") == as_timestamp(state_attr('calendar.feyenoord', 'start_time') | timestamp_local) | timestamp_custom("%H:%M") }}' but no default was specified. Currently 'timestamp_local' will return 'None', however this template will fail to render in Home Assistant core 2021.12
2021-10-11 11:21:16 WARNING (MainThread) [homeassistant.helpers.template] Template warning: 'as_timestamp' got invalid input 'None' when rendering template '{{ (now().strftime("%s")| int + (30*60)) | timestamp_custom("%H:%M") == as_timestamp(state_attr('calendar.feyenoord', 'start_time') | timestamp_local) | timestamp_custom("%H:%M") }}' but no default was specified. Currently 'as_timestamp' will return 'None', however this template will fail to render in Home Assistant core 2021.12
2021-10-11 11:21:16 WARNING (MainThread) [homeassistant.helpers.template] Template warning: 'timestamp_custom' got invalid input 'None' when rendering template '{{ (now().strftime("%s")| int + (30*60)) | timestamp_custom("%H:%M") == as_timestamp(state_attr('calendar.feyenoord', 'start_time') | timestamp_local) | timestamp_custom("%H:%M") }}' but no default was specified. Currently 'timestamp_custom' will return 'None', however this template will fail to render in Home Assistant core 2021.12
2021-10-11 11:21:16 WARNING (MainThread) [homeassistant.helpers.service] Unable to find referenced entities climate.radiator_zithoek
2021-10-11 11:21:31 ERROR (MainThread) [homeassistant] Error doing job: Task exception was never retrieved
Traceback (most recent call last):
  File "/usr/src/homeassistant/homeassistant/helpers/update_coordinator.py", line 134, in _handle_refresh_interval
    await self._async_refresh(log_failures=True, scheduled=True)
  File "/usr/src/homeassistant/homeassistant/helpers/update_coordinator.py", line 265, in _async_refresh
    update_callback()
  File "/usr/src/homeassistant/homeassistant/helpers/entity.py", line 456, in async_write_ha_state
    self._async_write_ha_state()
  File "/usr/src/homeassistant/homeassistant/helpers/entity.py", line 496, in _async_write_ha_state
    extra_state_attributes = self.device_state_attributes
  File "/config/custom_components/grocy/entity.py", line 142, in device_state_attributes
    return json.loads(json.dumps(data, cls=GrocyJSONEncoder))
  File "/usr/local/lib/python3.9/json/__init__.py", line 234, in dumps
    return cls(
  File "/usr/local/lib/python3.9/json/encoder.py", line 199, in encode
    chunks = self.iterencode(o, _one_shot=True)
  File "/usr/local/lib/python3.9/json/encoder.py", line 257, in iterencode
    return _iterencode(o, 0)
  File "/config/custom_components/grocy/json_encode.py", line 26, in default
    return json.JSONEncoder.default(self, o)
  File "/usr/local/lib/python3.9/json/encoder.py", line 179, in default
    raise TypeError(f'Object of type {o.__class__.__name__} '
TypeError: Object of type ProductBarcodeData is not JSON serializable
2021-10-11 11:21:34 WARNING (MainThread) [homeassistant.components.zha.core.channels.base] [0xE27B:1:0x0006]: async_initialize: all attempts have failed: [DeliveryError('[0xe27b:1:0x0006]: Message send failure'), DeliveryError('[0xe27b:1:0x0006]: Message send failure'), DeliveryError('[0xe27b:1:0x0006]: Message send failure'), DeliveryError('[0xe27b:1:0x0006]: Message send failure')]
2021-10-11 11:21:55 ERROR (SyncWorker_10) [homeassistant.components.command_line] Command failed: /config/scripts/get_shopping_list.py
2021-10-11 11:21:55 WARNING (SyncWorker_10) [homeassistant.components.command_line.sensor] Empty reply found when expecting JSON data
2021-10-11 11:22:00 WARNING (MainThread) [homeassistant.helpers.template] Template warning: 'timestamp_local' got invalid input 'None' when rendering template '{{ (now().strftime("%s")| int + (30*60)) | timestamp_custom("%H:%M") == as_timestamp(state_attr('calendar.feyenoord', 'start_time') | timestamp_local) | timestamp_custom("%H:%M") }}' but no default was specified. Currently 'timestamp_local' will return 'None', however this template will fail to render in Home Assistant core 2021.12
2021-10-11 11:22:00 WARNING (MainThread) [homeassistant.helpers.template] Template warning: 'as_timestamp' got invalid input 'None' when rendering template '{{ (now().strftime("%s")| int + (30*60)) | timestamp_custom("%H:%M") == as_timestamp(state_attr('calendar.feyenoord', 'start_time') | timestamp_local) | timestamp_custom("%H:%M") }}' but no default was specified. Currently 'as_timestamp' will return 'None', however this template will fail to render in Home Assistant core 2021.12
2021-10-11 11:22:00 WARNING (MainThread) [homeassistant.helpers.template] Template warning: 'timestamp_custom' got invalid input 'None' when rendering template '{{ (now().strftime("%s")| int + (30*60)) | timestamp_custom("%H:%M") == as_timestamp(state_attr('calendar.feyenoord', 'start_time') | timestamp_local) | timestamp_custom("%H:%M") }}' but no default was specified. Currently 'timestamp_custom' will return 'None', however this template will fail to render in Home Assistant core 2021.12
2021-10-11 11:22:00 WARNING (MainThread) [homeassistant.helpers.template] Template warning: 'timestamp_local' got invalid input 'None' when rendering template '{{ (now().strftime("%s")| int + (5*60)) | timestamp_custom("%H:%M") == as_timestamp(state_attr('calendar.feyenoord', 'start_time')  | timestamp_local) | timestamp_custom("%H:%M") }}' but no default was specified. Currently 'timestamp_local' will return 'None', however this template will fail to render in Home Assistant core 2021.12
2021-10-11 11:22:00 WARNING (MainThread) [homeassistant.helpers.template] Template warning: 'as_timestamp' got invalid input 'None' when rendering template '{{ (now().strftime("%s")| int + (5*60)) | timestamp_custom("%H:%M") == as_timestamp(state_attr('calendar.feyenoord', 'start_time')  | timestamp_local) | timestamp_custom("%H:%M") }}' but no default was specified. Currently 'as_timestamp' will return 'None', however this template will fail to render in Home Assistant core 2021.12
2021-10-11 11:22:00 WARNING (MainThread) [homeassistant.helpers.template] Template warning: 'timestamp_custom' got invalid input 'None' when rendering template '{{ (now().strftime("%s")| int + (5*60)) | timestamp_custom("%H:%M") == as_timestamp(state_attr('calendar.feyenoord', 'start_time')  | timestamp_local) | timestamp_custom("%H:%M") }}' but no default was specified. Currently 'timestamp_custom' will return 'None', however this template will fail to render in Home Assistant core 2021.12
2021-10-11 11:22:04 ERROR (MainThread) [homeassistant] Error doing job: Task exception was never retrieved
Traceback (most recent call last):
  File "/usr/src/homeassistant/homeassistant/helpers/update_coordinator.py", line 134, in _handle_refresh_interval
    await self._async_refresh(log_failures=True, scheduled=True)
  File "/usr/src/homeassistant/homeassistant/helpers/update_coordinator.py", line 265, in _async_refresh
    update_callback()
  File "/usr/src/homeassistant/homeassistant/helpers/entity.py", line 456, in async_write_ha_state
    self._async_write_ha_state()
  File "/usr/src/homeassistant/homeassistant/helpers/entity.py", line 496, in _async_write_ha_state
    extra_state_attributes = self.device_state_attributes
  File "/config/custom_components/grocy/entity.py", line 142, in device_state_attributes
    return json.loads(json.dumps(data, cls=GrocyJSONEncoder))
  File "/usr/local/lib/python3.9/json/__init__.py", line 234, in dumps
    return cls(
  File "/usr/local/lib/python3.9/json/encoder.py", line 199, in encode
    chunks = self.iterencode(o, _one_shot=True)
  File "/usr/local/lib/python3.9/json/encoder.py", line 257, in iterencode
    return _iterencode(o, 0)
  File "/config/custom_components/grocy/json_encode.py", line 26, in default
    return json.JSONEncoder.default(self, o)
  File "/usr/local/lib/python3.9/json/encoder.py", line 179, in default
    raise TypeError(f'Object of type {o.__class__.__name__} '
TypeError: Object of type ProductBarcodeData is not JSON serializable
2021-10-11 11:22:05 WARNING (MainThread) [homeassistant.helpers.entity] Update of sensor.recipies is taking over 10 seconds
2021-10-11 11:22:15 ERROR (MainThread) [homeassistant.helpers.template] Template variable error: list object has no element 6 when rendering '{{ state_attr('sensor.recipies', 'recepten')[states('input_number.recipe_id')|round].description.split('<li>')[6].split('<br />')[0]|replace('</li>','')}}'
2021-10-11 11:22:36 ERROR (MainThread) [homeassistant] Error doing job: Task exception was never retrieved
Traceback (most recent call last):
  File "/usr/src/homeassistant/homeassistant/helpers/update_coordinator.py", line 134, in _handle_refresh_interval
    await self._async_refresh(log_failures=True, scheduled=True)
  File "/usr/src/homeassistant/homeassistant/helpers/update_coordinator.py", line 265, in _async_refresh
    update_callback()
  File "/usr/src/homeassistant/homeassistant/helpers/entity.py", line 456, in async_write_ha_state
    self._async_write_ha_state()
  File "/usr/src/homeassistant/homeassistant/helpers/entity.py", line 496, in _async_write_ha_state
    extra_state_attributes = self.device_state_attributes
  File "/config/custom_components/grocy/entity.py", line 142, in device_state_attributes
    return json.loads(json.dumps(data, cls=GrocyJSONEncoder))
  File "/usr/local/lib/python3.9/json/__init__.py", line 234, in dumps
    return cls(
  File "/usr/local/lib/python3.9/json/encoder.py", line 199, in encode
    chunks = self.iterencode(o, _one_shot=True)
  File "/usr/local/lib/python3.9/json/encoder.py", line 257, in iterencode
    return _iterencode(o, 0)
  File "/config/custom_components/grocy/json_encode.py", line 26, in default
    return json.JSONEncoder.default(self, o)
  File "/usr/local/lib/python3.9/json/encoder.py", line 179, in default
    raise TypeError(f'Object of type {o.__class__.__name__} '
TypeError: Object of type ProductBarcodeData is not JSON serializable
2021-10-11 11:22:55 ERROR (SyncWorker_4) [homeassistant.components.command_line] Command failed: /config/scripts/get_shopping_list.py
2021-10-11 11:22:55 WARNING (SyncWorker_4) [homeassistant.components.command_line.sensor] Empty reply found when expecting JSON data
2021-10-11 11:23:00 WARNING (MainThread) [homeassistant.helpers.template] Template warning: 'timestamp_local' got invalid input 'None' when rendering template '{{ (now().strftime("%s")| int + (5*60)) | timestamp_custom("%H:%M") == as_timestamp(state_attr('calendar.feyenoord', 'start_time')  | timestamp_local) | timestamp_custom("%H:%M") }}' but no default was specified. Currently 'timestamp_local' will return 'None', however this template will fail to render in Home Assistant core 2021.12
2021-10-11 11:23:00 WARNING (MainThread) [homeassistant.helpers.template] Template warning: 'as_timestamp' got invalid input 'None' when rendering template '{{ (now().strftime("%s")| int + (5*60)) | timestamp_custom("%H:%M") == as_timestamp(state_attr('calendar.feyenoord', 'start_time')  | timestamp_local) | timestamp_custom("%H:%M") }}' but no default was specified. Currently 'as_timestamp' will return 'None', however this template will fail to render in Home Assistant core 2021.12
2021-10-11 11:23:00 WARNING (MainThread) [homeassistant.helpers.template] Template warning: 'timestamp_custom' got invalid input 'None' when rendering template '{{ (now().strftime("%s")| int + (5*60)) | timestamp_custom("%H:%M") == as_timestamp(state_attr('calendar.feyenoord', 'start_time')  | timestamp_local) | timestamp_custom("%H:%M") }}' but no default was specified. Currently 'timestamp_custom' will return 'None', however this template will fail to render in Home Assistant core 2021.12
2021-10-11 11:23:00 WARNING (MainThread) [homeassistant.helpers.template] Template warning: 'timestamp_local' got invalid input 'None' when rendering template '{{ (now().strftime("%s")| int + (30*60)) | timestamp_custom("%H:%M") == as_timestamp(state_attr('calendar.feyenoord', 'start_time') | timestamp_local) | timestamp_custom("%H:%M") }}' but no default was specified. Currently 'timestamp_local' will return 'None', however this template will fail to render in Home Assistant core 2021.12
2021-10-11 11:23:00 WARNING (MainThread) [homeassistant.helpers.template] Template warning: 'as_timestamp' got invalid input 'None' when rendering template '{{ (now().strftime("%s")| int + (30*60)) | timestamp_custom("%H:%M") == as_timestamp(state_attr('calendar.feyenoord', 'start_time') | timestamp_local) | timestamp_custom("%H:%M") }}' but no default was specified. Currently 'as_timestamp' will return 'None', however this template will fail to render in Home Assistant core 2021.12
2021-10-11 11:23:00 WARNING (MainThread) [homeassistant.helpers.template] Template warning: 'timestamp_custom' got invalid input 'None' when rendering template '{{ (now().strftime("%s")| int + (30*60)) | timestamp_custom("%H:%M") == as_timestamp(state_attr('calendar.feyenoord', 'start_time') | timestamp_local) | timestamp_custom("%H:%M") }}' but no default was specified. Currently 'timestamp_custom' will return 'None', however this template will fail to render in Home Assistant core 2021.12
2021-10-11 11:23:04 WARNING (Thread-105) [homeassistant.util.executor] Thread[SyncWorker_6] is still running at shutdown: File "/usr/local/lib/python3.9/threading.py", line 930, in _bootstrap
    self._bootstrap_inner()
  File "/usr/local/lib/python3.9/threading.py", line 973, in _bootstrap_inner
    self.run()
  File "/usr/local/lib/python3.9/threading.py", line 910, in run
    self._target(*self._args, **self._kwargs)
  File "/usr/local/lib/python3.9/concurrent/futures/thread.py", line 77, in _worker
    work_item.run()
  File "/usr/local/lib/python3.9/concurrent/futures/thread.py", line 52, in run
    result = self.fn(*self.args, **self.kwargs)
  File "/usr/src/homeassistant/homeassistant/components/command_line/sensor.py", line 103, in update
    self.data.update()
  File "/usr/src/homeassistant/homeassistant/components/command_line/sensor.py", line 174, in update
    self.value = check_output_or_log(command, self.timeout)
  File "/usr/src/homeassistant/homeassistant/components/command_line/__init__.py", line 36, in check_output_or_log
    return_value = subprocess.check_output(
  File "/usr/local/lib/python3.9/subprocess.py", line 424, in check_output
    return run(*popenargs, stdout=PIPE, timeout=timeout, check=True,
  File "/usr/local/lib/python3.9/subprocess.py", line 507, in run
    stdout, stderr = process.communicate(input, timeout=timeout)
  File "/usr/local/lib/python3.9/subprocess.py", line 1134, in communicate
    stdout, stderr = self._communicate(input, endtime, timeout)
  File "/usr/local/lib/python3.9/subprocess.py", line 1979, in _communicate
    ready = selector.select(timeout)
  File "/usr/local/lib/python3.9/selectors.py", line 416, in select
    fd_event_list = self._selector.poll(timeout)
2021-10-11 11:23:04 ERROR (MainThread) [homeassistant] Error doing job: Future exception was never retrieved
Traceback (most recent call last):
  File "/usr/local/lib/python3.9/concurrent/futures/thread.py", line 52, in run
    result = self.fn(*self.args, **self.kwargs)
  File "/usr/src/homeassistant/homeassistant/components/command_line/sensor.py", line 103, in update
    self.data.update()
  File "/usr/src/homeassistant/homeassistant/components/command_line/sensor.py", line 174, in update
    self.value = check_output_or_log(command, self.timeout)
  File "/usr/src/homeassistant/homeassistant/components/command_line/__init__.py", line 36, in check_output_or_log
    return_value = subprocess.check_output(
  File "/usr/local/lib/python3.9/subprocess.py", line 424, in check_output
    return run(*popenargs, stdout=PIPE, timeout=timeout, check=True,
  File "/usr/local/lib/python3.9/subprocess.py", line 507, in run
    stdout, stderr = process.communicate(input, timeout=timeout)
  File "/usr/local/lib/python3.9/subprocess.py", line 1134, in communicate
    stdout, stderr = self._communicate(input, endtime, timeout)
  File "/usr/local/lib/python3.9/subprocess.py", line 1979, in _communicate
    ready = selector.select(timeout)
  File "/usr/local/lib/python3.9/selectors.py", line 416, in select
    fd_event_list = self._selector.poll(timeout)
SystemExit
