2021-09-12 15:53:03 WARNING (SyncWorker_1) [homeassistant.loader] We found a custom integration browser_mod which has not been tested by Home Assistant. This component might cause stability problems, be sure to disable it if you experience issues with Home Assistant
2021-09-12 15:53:03 WARNING (SyncWorker_1) [homeassistant.loader] We found a custom integration ovapi which has not been tested by Home Assistant. This component might cause stability problems, be sure to disable it if you experience issues with Home Assistant
2021-09-12 15:53:03 WARNING (SyncWorker_0) [homeassistant.loader] We found a custom integration hacs which has not been tested by Home Assistant. This component might cause stability problems, be sure to disable it if you experience issues with Home Assistant
2021-09-12 15:53:03 WARNING (SyncWorker_3) [homeassistant.loader] We found a custom integration climate_group which has not been tested by Home Assistant. This component might cause stability problems, be sure to disable it if you experience issues with Home Assistant
2021-09-12 15:53:03 WARNING (SyncWorker_0) [homeassistant.loader] We found a custom integration grocy which has not been tested by Home Assistant. This component might cause stability problems, be sure to disable it if you experience issues with Home Assistant
2021-09-12 15:53:03 WARNING (SyncWorker_1) [homeassistant.loader] We found a custom integration knmi which has not been tested by Home Assistant. This component might cause stability problems, be sure to disable it if you experience issues with Home Assistant
2021-09-12 15:53:03 WARNING (SyncWorker_3) [homeassistant.loader] We found a custom integration breaking_changes which has not been tested by Home Assistant. This component might cause stability problems, be sure to disable it if you experience issues with Home Assistant
2021-09-12 15:53:03 WARNING (SyncWorker_2) [homeassistant.loader] We found a custom integration readme which has not been tested by Home Assistant. This component might cause stability problems, be sure to disable it if you experience issues with Home Assistant
2021-09-12 15:53:03 WARNING (SyncWorker_4) [homeassistant.loader] We found a custom integration buienalarm which has not been tested by Home Assistant. This component might cause stability problems, be sure to disable it if you experience issues with Home Assistant
2021-09-12 15:53:03 WARNING (SyncWorker_1) [homeassistant.loader] We found a custom integration adaptive_lighting which has not been tested by Home Assistant. This component might cause stability problems, be sure to disable it if you experience issues with Home Assistant
2021-09-12 15:53:03 WARNING (SyncWorker_0) [homeassistant.loader] We found a custom integration neerslag which has not been tested by Home Assistant. This component might cause stability problems, be sure to disable it if you experience issues with Home Assistant
2021-09-12 15:53:03 WARNING (SyncWorker_5) [homeassistant.loader] We found a custom integration monitor_docker which has not been tested by Home Assistant. This component might cause stability problems, be sure to disable it if you experience issues with Home Assistant
2021-09-12 15:53:07 ERROR (MainThread) [homeassistant.components.weather] The buienradar platform for the weather integration does not support platform setup. Please remove it from your config.
2021-09-12 15:53:08 ERROR (MainThread) [homeassistant.components.camera] The buienradar platform for the camera integration does not support platform setup. Please remove it from your config.
2021-09-12 15:53:09 WARNING (MainThread) [homeassistant.components.heos] 192.168.178.106 is not logged in to a HEOS account and will be unable to retrieve HEOS favorites: Use the 'heos.sign_in' service to sign-in to a HEOS account
2021-09-12 15:53:09 WARNING (MainThread) [zigpy.zcl] Unknown cluster 61184
2021-09-12 15:53:09 WARNING (MainThread) [zigpy.zcl] Unknown cluster 61184
2021-09-12 15:53:11 ERROR (MainThread) [homeassistant.components.binary_sensor] grocy: Error on device update!
Traceback (most recent call last):
  File "/usr/src/homeassistant/homeassistant/helpers/entity_platform.py", line 431, in _async_add_entity
    await entity.async_device_update(warning=False)
  File "/usr/src/homeassistant/homeassistant/helpers/entity.py", line 633, in async_device_update
    await task
  File "/config/custom_components/grocy/entity.py", line 57, in async_update
    await self.coordinator.async_request_refresh()
  File "/usr/src/homeassistant/homeassistant/helpers/update_coordinator.py", line 141, in async_request_refresh
    await self._debounced_refresh.async_call()
  File "/usr/src/homeassistant/homeassistant/helpers/debounce.py", line 78, in async_call
    await task
  File "/usr/src/homeassistant/homeassistant/helpers/update_coordinator.py", line 165, in async_refresh
    await self._async_refresh(log_failures=True)
  File "/usr/src/homeassistant/homeassistant/helpers/update_coordinator.py", line 265, in _async_refresh
    update_callback()
  File "/usr/src/homeassistant/homeassistant/helpers/entity.py", line 464, in async_write_ha_state
    self._async_write_ha_state()
  File "/usr/src/homeassistant/homeassistant/helpers/entity.py", line 505, in _async_write_ha_state
    extra_state_attributes = self.device_state_attributes
  File "/config/custom_components/grocy/entity.py", line 142, in device_state_attributes
    return json.loads(json.dumps(data, cls=GrocyJSONEncoder))
  File "/usr/local/lib/python3.9/json/__init__.py", line 234, in dumps
    return cls(
  File "/usr/local/lib/python3.9/json/encoder.py", line 199, in encode
    chunks = self.iterencode(o, _one_shot=True)
  File "/usr/local/lib/python3.9/json/encoder.py", line 257, in iterencode
    return _iterencode(o, 0)
  File "/config/custom_components/grocy/json_encode.py", line 26, in default
    return json.JSONEncoder.default(self, o)
  File "/usr/local/lib/python3.9/json/encoder.py", line 179, in default
    raise TypeError(f'Object of type {o.__class__.__name__} '
TypeError: Object of type ProductBarcodeData is not JSON serializable
2021-09-12 15:53:17 ERROR (MainThread) [homeassistant.components.sensor] The buienradar platform for the sensor integration does not support platform setup. Please remove it from your config.
2021-09-12 15:53:17 ERROR (SyncWorker_4) [homeassistant.components.command_line] Command failed: /config/scripts/get_shopping_list.py
2021-09-12 15:53:17 WARNING (SyncWorker_4) [homeassistant.components.command_line.sensor] Empty reply found when expecting JSON data
2021-09-12 15:53:20 ERROR (MainThread) [homeassistant.components.sensor] grocy: Error on device update!
Traceback (most recent call last):
  File "/usr/src/homeassistant/homeassistant/helpers/entity_platform.py", line 431, in _async_add_entity
    await entity.async_device_update(warning=False)
  File "/usr/src/homeassistant/homeassistant/helpers/entity.py", line 633, in async_device_update
    await task
  File "/config/custom_components/grocy/entity.py", line 57, in async_update
    await self.coordinator.async_request_refresh()
  File "/usr/src/homeassistant/homeassistant/helpers/update_coordinator.py", line 141, in async_request_refresh
    await self._debounced_refresh.async_call()
  File "/usr/src/homeassistant/homeassistant/helpers/debounce.py", line 78, in async_call
    await task
  File "/usr/src/homeassistant/homeassistant/helpers/update_coordinator.py", line 165, in async_refresh
    await self._async_refresh(log_failures=True)
  File "/usr/src/homeassistant/homeassistant/helpers/update_coordinator.py", line 265, in _async_refresh
    update_callback()
  File "/usr/src/homeassistant/homeassistant/helpers/entity.py", line 464, in async_write_ha_state
    self._async_write_ha_state()
  File "/usr/src/homeassistant/homeassistant/helpers/entity.py", line 505, in _async_write_ha_state
    extra_state_attributes = self.device_state_attributes
  File "/config/custom_components/grocy/entity.py", line 142, in device_state_attributes
    return json.loads(json.dumps(data, cls=GrocyJSONEncoder))
  File "/usr/local/lib/python3.9/json/__init__.py", line 234, in dumps
    return cls(
  File "/usr/local/lib/python3.9/json/encoder.py", line 199, in encode
    chunks = self.iterencode(o, _one_shot=True)
  File "/usr/local/lib/python3.9/json/encoder.py", line 257, in iterencode
    return _iterencode(o, 0)
  File "/config/custom_components/grocy/json_encode.py", line 26, in default
    return json.JSONEncoder.default(self, o)
  File "/usr/local/lib/python3.9/json/encoder.py", line 179, in default
    raise TypeError(f'Object of type {o.__class__.__name__} '
TypeError: Object of type ProductBarcodeData is not JSON serializable
2021-09-12 15:53:32 ERROR (MainThread) [homeassistant.helpers.template] Template variable error: list object has no element 6 when rendering '{{ state_attr('sensor.recipies', 'recepten')[states('input_number.recipe_id')|round].description.split('<li>')[6].split('<br />')[0]|replace('</li>','')}}'
2021-09-12 15:53:32 ERROR (MainThread) [homeassistant.helpers.event] Error while processing template: Template("{{ state_attr('sensor.recipies', 'recepten')[states('input_number.recipe_id')|round].description.split('<li>')[6].split('<br />')[0]|replace('</li>','')}}")
Traceback (most recent call last):
  File "/usr/src/homeassistant/homeassistant/helpers/template.py", line 394, in async_render
    render_result = _render_with_context(self.template, compiled, **kwargs)
  File "/usr/src/homeassistant/homeassistant/helpers/template.py", line 1477, in _render_with_context
    return template.render(**kwargs)
  File "/usr/local/lib/python3.9/site-packages/jinja2/environment.py", line 1304, in render
    self.environment.handle_exception()
  File "/usr/local/lib/python3.9/site-packages/jinja2/environment.py", line 925, in handle_exception
    raise rewrite_traceback_stack(source=source)
  File "<template>", line 1, in top-level template code
  File "/usr/local/lib/python3.9/site-packages/jinja2/sandbox.py", line 326, in getattr
    value = getattr(obj, attribute)
  File "/usr/src/homeassistant/homeassistant/helpers/template.py", line 1501, in _fail_with_undefined_error
    raise ex
  File "/usr/src/homeassistant/homeassistant/helpers/template.py", line 1493, in _fail_with_undefined_error
    return super()._fail_with_undefined_error(*args, **kwargs)
jinja2.exceptions.UndefinedError: list object has no element 6

The above exception was the direct cause of the following exception:

Traceback (most recent call last):
  File "/usr/src/homeassistant/homeassistant/helpers/template.py", line 510, in async_render_to_info
    render_info._result = self.async_render(variables, strict=strict, **kwargs)
  File "/usr/src/homeassistant/homeassistant/helpers/template.py", line 396, in async_render
    raise TemplateError(err) from err
homeassistant.exceptions.TemplateError: UndefinedError: list object has no element 6
2021-09-12 15:53:32 ERROR (MainThread) [homeassistant.helpers.template] Template variable error: list object has no element 6 when rendering '{{ state_attr('sensor.recipies', 'recepten')[states('input_number.recipe_id')|round].description.split('<li>')[6].split('<br />')[0]|replace('</li>','')}}'
2021-09-12 15:53:32 ERROR (MainThread) [homeassistant.components.template.template_entity] TemplateError('UndefinedError: list object has no element 6') while processing template 'Template("{{ state_attr('sensor.recipies', 'recepten')[states('input_number.recipe_id')|round].description.split('<li>')[6].split('<br />')[0]|replace('</li>','')}}")' for attribute 'step_6' in entity 'sensor.cooking'
2021-09-12 15:53:32 ERROR (MainThread) [homeassistant.helpers.event] Error while processing template: Template("{%- for i in state_attr('sensor.grocy_stock', 'products') %} {%- if i.id == 93 %} {{ i.available_amount | round }} {%- endif %} {%- endfor %}")
Traceback (most recent call last):
  File "/usr/src/homeassistant/homeassistant/helpers/template.py", line 394, in async_render
    render_result = _render_with_context(self.template, compiled, **kwargs)
  File "/usr/src/homeassistant/homeassistant/helpers/template.py", line 1477, in _render_with_context
    return template.render(**kwargs)
  File "/usr/local/lib/python3.9/site-packages/jinja2/environment.py", line 1304, in render
    self.environment.handle_exception()
  File "/usr/local/lib/python3.9/site-packages/jinja2/environment.py", line 925, in handle_exception
    raise rewrite_traceback_stack(source=source)
  File "<template>", line 1, in top-level template code
TypeError: 'NoneType' object is not iterable

The above exception was the direct cause of the following exception:

Traceback (most recent call last):
  File "/usr/src/homeassistant/homeassistant/helpers/template.py", line 510, in async_render_to_info
    render_info._result = self.async_render(variables, strict=strict, **kwargs)
  File "/usr/src/homeassistant/homeassistant/helpers/template.py", line 396, in async_render
    raise TemplateError(err) from err
homeassistant.exceptions.TemplateError: TypeError: 'NoneType' object is not iterable
2021-09-12 15:53:32 ERROR (MainThread) [homeassistant.components.template.template_entity] TemplateError('TypeError: 'NoneType' object is not iterable') while processing template 'Template("{%- for i in state_attr('sensor.grocy_stock', 'products') %} {%- if i.id == 93 %} {{ i.available_amount | round }} {%- endif %} {%- endfor %}")' for attribute '_attr_native_value' in entity 'sensor.kattenvoer'
2021-09-12 15:53:52 ERROR (MainThread) [homeassistant] Error doing job: Task exception was never retrieved
Traceback (most recent call last):
  File "/usr/src/homeassistant/homeassistant/helpers/update_coordinator.py", line 134, in _handle_refresh_interval
    await self._async_refresh(log_failures=True, scheduled=True)
  File "/usr/src/homeassistant/homeassistant/helpers/update_coordinator.py", line 265, in _async_refresh
    update_callback()
  File "/usr/src/homeassistant/homeassistant/helpers/entity.py", line 464, in async_write_ha_state
    self._async_write_ha_state()
  File "/usr/src/homeassistant/homeassistant/helpers/entity.py", line 505, in _async_write_ha_state
    extra_state_attributes = self.device_state_attributes
  File "/config/custom_components/grocy/entity.py", line 142, in device_state_attributes
    return json.loads(json.dumps(data, cls=GrocyJSONEncoder))
  File "/usr/local/lib/python3.9/json/__init__.py", line 234, in dumps
    return cls(
  File "/usr/local/lib/python3.9/json/encoder.py", line 199, in encode
    chunks = self.iterencode(o, _one_shot=True)
  File "/usr/local/lib/python3.9/json/encoder.py", line 257, in iterencode
    return _iterencode(o, 0)
  File "/config/custom_components/grocy/json_encode.py", line 26, in default
    return json.JSONEncoder.default(self, o)
  File "/usr/local/lib/python3.9/json/encoder.py", line 179, in default
    raise TypeError(f'Object of type {o.__class__.__name__} '
TypeError: Object of type ProductBarcodeData is not JSON serializable
2021-09-12 15:54:17 ERROR (SyncWorker_9) [homeassistant.components.command_line] Command failed: /config/scripts/get_shopping_list.py
2021-09-12 15:54:17 WARNING (SyncWorker_9) [homeassistant.components.command_line.sensor] Empty reply found when expecting JSON data
2021-09-12 15:54:25 ERROR (MainThread) [homeassistant] Error doing job: Task exception was never retrieved
Traceback (most recent call last):
  File "/usr/src/homeassistant/homeassistant/helpers/update_coordinator.py", line 134, in _handle_refresh_interval
    await self._async_refresh(log_failures=True, scheduled=True)
  File "/usr/src/homeassistant/homeassistant/helpers/update_coordinator.py", line 265, in _async_refresh
    update_callback()
  File "/usr/src/homeassistant/homeassistant/helpers/entity.py", line 464, in async_write_ha_state
    self._async_write_ha_state()
  File "/usr/src/homeassistant/homeassistant/helpers/entity.py", line 505, in _async_write_ha_state
    extra_state_attributes = self.device_state_attributes
  File "/config/custom_components/grocy/entity.py", line 142, in device_state_attributes
    return json.loads(json.dumps(data, cls=GrocyJSONEncoder))
  File "/usr/local/lib/python3.9/json/__init__.py", line 234, in dumps
    return cls(
  File "/usr/local/lib/python3.9/json/encoder.py", line 199, in encode
    chunks = self.iterencode(o, _one_shot=True)
  File "/usr/local/lib/python3.9/json/encoder.py", line 257, in iterencode
    return _iterencode(o, 0)
  File "/config/custom_components/grocy/json_encode.py", line 26, in default
    return json.JSONEncoder.default(self, o)
  File "/usr/local/lib/python3.9/json/encoder.py", line 179, in default
    raise TypeError(f'Object of type {o.__class__.__name__} '
TypeError: Object of type ProductBarcodeData is not JSON serializable
2021-09-12 15:54:32 ERROR (MainThread) [homeassistant.helpers.template] Template variable error: list object has no element 6 when rendering '{{ state_attr('sensor.recipies', 'recepten')[states('input_number.recipe_id')|round].description.split('<li>')[6].split('<br />')[0]|replace('</li>','')}}'
2021-09-12 15:54:58 ERROR (MainThread) [homeassistant] Error doing job: Task exception was never retrieved
Traceback (most recent call last):
  File "/usr/src/homeassistant/homeassistant/helpers/update_coordinator.py", line 134, in _handle_refresh_interval
    await self._async_refresh(log_failures=True, scheduled=True)
  File "/usr/src/homeassistant/homeassistant/helpers/update_coordinator.py", line 265, in _async_refresh
    update_callback()
  File "/usr/src/homeassistant/homeassistant/helpers/entity.py", line 464, in async_write_ha_state
    self._async_write_ha_state()
  File "/usr/src/homeassistant/homeassistant/helpers/entity.py", line 505, in _async_write_ha_state
    extra_state_attributes = self.device_state_attributes
  File "/config/custom_components/grocy/entity.py", line 142, in device_state_attributes
    return json.loads(json.dumps(data, cls=GrocyJSONEncoder))
  File "/usr/local/lib/python3.9/json/__init__.py", line 234, in dumps
    return cls(
  File "/usr/local/lib/python3.9/json/encoder.py", line 199, in encode
    chunks = self.iterencode(o, _one_shot=True)
  File "/usr/local/lib/python3.9/json/encoder.py", line 257, in iterencode
    return _iterencode(o, 0)
  File "/config/custom_components/grocy/json_encode.py", line 26, in default
    return json.JSONEncoder.default(self, o)
  File "/usr/local/lib/python3.9/json/encoder.py", line 179, in default
    raise TypeError(f'Object of type {o.__class__.__name__} '
TypeError: Object of type ProductBarcodeData is not JSON serializable
2021-09-12 15:55:17 ERROR (SyncWorker_5) [homeassistant.components.command_line] Command failed: /config/scripts/get_shopping_list.py
2021-09-12 15:55:17 WARNING (SyncWorker_5) [homeassistant.components.command_line.sensor] Empty reply found when expecting JSON data
2021-09-12 15:55:30 ERROR (MainThread) [homeassistant] Error doing job: Task exception was never retrieved
Traceback (most recent call last):
  File "/usr/src/homeassistant/homeassistant/helpers/update_coordinator.py", line 134, in _handle_refresh_interval
    await self._async_refresh(log_failures=True, scheduled=True)
  File "/usr/src/homeassistant/homeassistant/helpers/update_coordinator.py", line 265, in _async_refresh
    update_callback()
  File "/usr/src/homeassistant/homeassistant/helpers/entity.py", line 464, in async_write_ha_state
    self._async_write_ha_state()
  File "/usr/src/homeassistant/homeassistant/helpers/entity.py", line 505, in _async_write_ha_state
    extra_state_attributes = self.device_state_attributes
  File "/config/custom_components/grocy/entity.py", line 142, in device_state_attributes
    return json.loads(json.dumps(data, cls=GrocyJSONEncoder))
  File "/usr/local/lib/python3.9/json/__init__.py", line 234, in dumps
    return cls(
  File "/usr/local/lib/python3.9/json/encoder.py", line 199, in encode
    chunks = self.iterencode(o, _one_shot=True)
  File "/usr/local/lib/python3.9/json/encoder.py", line 257, in iterencode
    return _iterencode(o, 0)
  File "/config/custom_components/grocy/json_encode.py", line 26, in default
    return json.JSONEncoder.default(self, o)
  File "/usr/local/lib/python3.9/json/encoder.py", line 179, in default
    raise TypeError(f'Object of type {o.__class__.__name__} '
TypeError: Object of type ProductBarcodeData is not JSON serializable
2021-09-12 15:55:32 ERROR (MainThread) [homeassistant.helpers.template] Template variable error: list object has no element 6 when rendering '{{ state_attr('sensor.recipies', 'recepten')[states('input_number.recipe_id')|round].description.split('<li>')[6].split('<br />')[0]|replace('</li>','')}}'
2021-09-12 15:56:03 ERROR (MainThread) [homeassistant] Error doing job: Task exception was never retrieved
Traceback (most recent call last):
  File "/usr/src/homeassistant/homeassistant/helpers/update_coordinator.py", line 134, in _handle_refresh_interval
    await self._async_refresh(log_failures=True, scheduled=True)
  File "/usr/src/homeassistant/homeassistant/helpers/update_coordinator.py", line 265, in _async_refresh
    update_callback()
  File "/usr/src/homeassistant/homeassistant/helpers/entity.py", line 464, in async_write_ha_state
    self._async_write_ha_state()
  File "/usr/src/homeassistant/homeassistant/helpers/entity.py", line 505, in _async_write_ha_state
    extra_state_attributes = self.device_state_attributes
  File "/config/custom_components/grocy/entity.py", line 142, in device_state_attributes
    return json.loads(json.dumps(data, cls=GrocyJSONEncoder))
  File "/usr/local/lib/python3.9/json/__init__.py", line 234, in dumps
    return cls(
  File "/usr/local/lib/python3.9/json/encoder.py", line 199, in encode
    chunks = self.iterencode(o, _one_shot=True)
  File "/usr/local/lib/python3.9/json/encoder.py", line 257, in iterencode
    return _iterencode(o, 0)
  File "/config/custom_components/grocy/json_encode.py", line 26, in default
    return json.JSONEncoder.default(self, o)
  File "/usr/local/lib/python3.9/json/encoder.py", line 179, in default
    raise TypeError(f'Object of type {o.__class__.__name__} '
TypeError: Object of type ProductBarcodeData is not JSON serializable
2021-09-12 15:56:17 ERROR (SyncWorker_1) [homeassistant.components.command_line] Command failed: /config/scripts/get_shopping_list.py
2021-09-12 15:56:17 WARNING (SyncWorker_1) [homeassistant.components.command_line.sensor] Empty reply found when expecting JSON data
2021-09-12 15:56:32 ERROR (MainThread) [homeassistant.helpers.template] Template variable error: list object has no element 6 when rendering '{{ state_attr('sensor.recipies', 'recepten')[states('input_number.recipe_id')|round].description.split('<li>')[6].split('<br />')[0]|replace('</li>','')}}'
2021-09-12 15:56:35 ERROR (MainThread) [homeassistant] Error doing job: Task exception was never retrieved
Traceback (most recent call last):
  File "/usr/src/homeassistant/homeassistant/helpers/update_coordinator.py", line 134, in _handle_refresh_interval
    await self._async_refresh(log_failures=True, scheduled=True)
  File "/usr/src/homeassistant/homeassistant/helpers/update_coordinator.py", line 265, in _async_refresh
    update_callback()
  File "/usr/src/homeassistant/homeassistant/helpers/entity.py", line 464, in async_write_ha_state
    self._async_write_ha_state()
  File "/usr/src/homeassistant/homeassistant/helpers/entity.py", line 505, in _async_write_ha_state
    extra_state_attributes = self.device_state_attributes
  File "/config/custom_components/grocy/entity.py", line 142, in device_state_attributes
    return json.loads(json.dumps(data, cls=GrocyJSONEncoder))
  File "/usr/local/lib/python3.9/json/__init__.py", line 234, in dumps
    return cls(
  File "/usr/local/lib/python3.9/json/encoder.py", line 199, in encode
    chunks = self.iterencode(o, _one_shot=True)
  File "/usr/local/lib/python3.9/json/encoder.py", line 257, in iterencode
    return _iterencode(o, 0)
  File "/config/custom_components/grocy/json_encode.py", line 26, in default
    return json.JSONEncoder.default(self, o)
  File "/usr/local/lib/python3.9/json/encoder.py", line 179, in default
    raise TypeError(f'Object of type {o.__class__.__name__} '
TypeError: Object of type ProductBarcodeData is not JSON serializable
2021-09-12 15:57:07 ERROR (MainThread) [homeassistant] Error doing job: Task exception was never retrieved
Traceback (most recent call last):
  File "/usr/src/homeassistant/homeassistant/helpers/update_coordinator.py", line 134, in _handle_refresh_interval
    await self._async_refresh(log_failures=True, scheduled=True)
  File "/usr/src/homeassistant/homeassistant/helpers/update_coordinator.py", line 265, in _async_refresh
    update_callback()
  File "/usr/src/homeassistant/homeassistant/helpers/entity.py", line 464, in async_write_ha_state
    self._async_write_ha_state()
  File "/usr/src/homeassistant/homeassistant/helpers/entity.py", line 505, in _async_write_ha_state
    extra_state_attributes = self.device_state_attributes
  File "/config/custom_components/grocy/entity.py", line 142, in device_state_attributes
    return json.loads(json.dumps(data, cls=GrocyJSONEncoder))
  File "/usr/local/lib/python3.9/json/__init__.py", line 234, in dumps
    return cls(
  File "/usr/local/lib/python3.9/json/encoder.py", line 199, in encode
    chunks = self.iterencode(o, _one_shot=True)
  File "/usr/local/lib/python3.9/json/encoder.py", line 257, in iterencode
    return _iterencode(o, 0)
  File "/config/custom_components/grocy/json_encode.py", line 26, in default
    return json.JSONEncoder.default(self, o)
  File "/usr/local/lib/python3.9/json/encoder.py", line 179, in default
    raise TypeError(f'Object of type {o.__class__.__name__} '
TypeError: Object of type ProductBarcodeData is not JSON serializable
2021-09-12 15:57:17 ERROR (SyncWorker_5) [homeassistant.components.command_line] Command failed: /config/scripts/get_shopping_list.py
2021-09-12 15:57:17 WARNING (SyncWorker_5) [homeassistant.components.command_line.sensor] Empty reply found when expecting JSON data
2021-09-12 15:57:32 ERROR (MainThread) [homeassistant.helpers.template] Template variable error: list object has no element 6 when rendering '{{ state_attr('sensor.recipies', 'recepten')[states('input_number.recipe_id')|round].description.split('<li>')[6].split('<br />')[0]|replace('</li>','')}}'
2021-09-12 15:57:39 ERROR (MainThread) [homeassistant] Error doing job: Task exception was never retrieved
Traceback (most recent call last):
  File "/usr/src/homeassistant/homeassistant/helpers/update_coordinator.py", line 134, in _handle_refresh_interval
    await self._async_refresh(log_failures=True, scheduled=True)
  File "/usr/src/homeassistant/homeassistant/helpers/update_coordinator.py", line 265, in _async_refresh
    update_callback()
  File "/usr/src/homeassistant/homeassistant/helpers/entity.py", line 464, in async_write_ha_state
    self._async_write_ha_state()
  File "/usr/src/homeassistant/homeassistant/helpers/entity.py", line 505, in _async_write_ha_state
    extra_state_attributes = self.device_state_attributes
  File "/config/custom_components/grocy/entity.py", line 142, in device_state_attributes
    return json.loads(json.dumps(data, cls=GrocyJSONEncoder))
  File "/usr/local/lib/python3.9/json/__init__.py", line 234, in dumps
    return cls(
  File "/usr/local/lib/python3.9/json/encoder.py", line 199, in encode
    chunks = self.iterencode(o, _one_shot=True)
  File "/usr/local/lib/python3.9/json/encoder.py", line 257, in iterencode
    return _iterencode(o, 0)
  File "/config/custom_components/grocy/json_encode.py", line 26, in default
    return json.JSONEncoder.default(self, o)
  File "/usr/local/lib/python3.9/json/encoder.py", line 179, in default
    raise TypeError(f'Object of type {o.__class__.__name__} '
TypeError: Object of type ProductBarcodeData is not JSON serializable
2021-09-12 15:58:11 ERROR (MainThread) [homeassistant] Error doing job: Task exception was never retrieved
Traceback (most recent call last):
  File "/usr/src/homeassistant/homeassistant/helpers/update_coordinator.py", line 134, in _handle_refresh_interval
    await self._async_refresh(log_failures=True, scheduled=True)
  File "/usr/src/homeassistant/homeassistant/helpers/update_coordinator.py", line 265, in _async_refresh
    update_callback()
  File "/usr/src/homeassistant/homeassistant/helpers/entity.py", line 464, in async_write_ha_state
    self._async_write_ha_state()
  File "/usr/src/homeassistant/homeassistant/helpers/entity.py", line 505, in _async_write_ha_state
    extra_state_attributes = self.device_state_attributes
  File "/config/custom_components/grocy/entity.py", line 142, in device_state_attributes
    return json.loads(json.dumps(data, cls=GrocyJSONEncoder))
  File "/usr/local/lib/python3.9/json/__init__.py", line 234, in dumps
    return cls(
  File "/usr/local/lib/python3.9/json/encoder.py", line 199, in encode
    chunks = self.iterencode(o, _one_shot=True)
  File "/usr/local/lib/python3.9/json/encoder.py", line 257, in iterencode
    return _iterencode(o, 0)
  File "/config/custom_components/grocy/json_encode.py", line 26, in default
    return json.JSONEncoder.default(self, o)
  File "/usr/local/lib/python3.9/json/encoder.py", line 179, in default
    raise TypeError(f'Object of type {o.__class__.__name__} '
TypeError: Object of type ProductBarcodeData is not JSON serializable
2021-09-12 15:58:17 ERROR (SyncWorker_3) [homeassistant.components.command_line] Command failed: /config/scripts/get_shopping_list.py
2021-09-12 15:58:17 WARNING (SyncWorker_3) [homeassistant.components.command_line.sensor] Empty reply found when expecting JSON data
2021-09-12 15:58:32 ERROR (MainThread) [homeassistant.helpers.template] Template variable error: list object has no element 6 when rendering '{{ state_attr('sensor.recipies', 'recepten')[states('input_number.recipe_id')|round].description.split('<li>')[6].split('<br />')[0]|replace('</li>','')}}'
2021-09-12 15:58:33 ERROR (MainThread) [homeassistant.components.shell_command] Error running command: `/config/scripts/ha_gitpush.sh`, return code: 128
NoneType: None
2021-09-12 15:58:43 ERROR (MainThread) [homeassistant] Error doing job: Task exception was never retrieved
Traceback (most recent call last):
  File "/usr/src/homeassistant/homeassistant/helpers/update_coordinator.py", line 134, in _handle_refresh_interval
    await self._async_refresh(log_failures=True, scheduled=True)
  File "/usr/src/homeassistant/homeassistant/helpers/update_coordinator.py", line 265, in _async_refresh
    update_callback()
  File "/usr/src/homeassistant/homeassistant/helpers/entity.py", line 464, in async_write_ha_state
    self._async_write_ha_state()
  File "/usr/src/homeassistant/homeassistant/helpers/entity.py", line 505, in _async_write_ha_state
    extra_state_attributes = self.device_state_attributes
  File "/config/custom_components/grocy/entity.py", line 142, in device_state_attributes
    return json.loads(json.dumps(data, cls=GrocyJSONEncoder))
  File "/usr/local/lib/python3.9/json/__init__.py", line 234, in dumps
    return cls(
  File "/usr/local/lib/python3.9/json/encoder.py", line 199, in encode
    chunks = self.iterencode(o, _one_shot=True)
  File "/usr/local/lib/python3.9/json/encoder.py", line 257, in iterencode
    return _iterencode(o, 0)
  File "/config/custom_components/grocy/json_encode.py", line 26, in default
    return json.JSONEncoder.default(self, o)
  File "/usr/local/lib/python3.9/json/encoder.py", line 179, in default
    raise TypeError(f'Object of type {o.__class__.__name__} '
TypeError: Object of type ProductBarcodeData is not JSON serializable
2021-09-12 15:59:15 ERROR (MainThread) [homeassistant] Error doing job: Task exception was never retrieved
Traceback (most recent call last):
  File "/usr/src/homeassistant/homeassistant/helpers/update_coordinator.py", line 134, in _handle_refresh_interval
    await self._async_refresh(log_failures=True, scheduled=True)
  File "/usr/src/homeassistant/homeassistant/helpers/update_coordinator.py", line 265, in _async_refresh
    update_callback()
  File "/usr/src/homeassistant/homeassistant/helpers/entity.py", line 464, in async_write_ha_state
    self._async_write_ha_state()
  File "/usr/src/homeassistant/homeassistant/helpers/entity.py", line 505, in _async_write_ha_state
    extra_state_attributes = self.device_state_attributes
  File "/config/custom_components/grocy/entity.py", line 142, in device_state_attributes
    return json.loads(json.dumps(data, cls=GrocyJSONEncoder))
  File "/usr/local/lib/python3.9/json/__init__.py", line 234, in dumps
    return cls(
  File "/usr/local/lib/python3.9/json/encoder.py", line 199, in encode
    chunks = self.iterencode(o, _one_shot=True)
  File "/usr/local/lib/python3.9/json/encoder.py", line 257, in iterencode
    return _iterencode(o, 0)
  File "/config/custom_components/grocy/json_encode.py", line 26, in default
    return json.JSONEncoder.default(self, o)
  File "/usr/local/lib/python3.9/json/encoder.py", line 179, in default
    raise TypeError(f'Object of type {o.__class__.__name__} '
TypeError: Object of type ProductBarcodeData is not JSON serializable
2021-09-12 15:59:17 ERROR (SyncWorker_10) [homeassistant.components.command_line] Command failed: /config/scripts/get_shopping_list.py
2021-09-12 15:59:17 WARNING (SyncWorker_10) [homeassistant.components.command_line.sensor] Empty reply found when expecting JSON data
2021-09-12 15:59:32 ERROR (MainThread) [homeassistant.helpers.template] Template variable error: list object has no element 6 when rendering '{{ state_attr('sensor.recipies', 'recepten')[states('input_number.recipe_id')|round].description.split('<li>')[6].split('<br />')[0]|replace('</li>','')}}'
2021-09-12 15:59:47 ERROR (MainThread) [homeassistant] Error doing job: Task exception was never retrieved
Traceback (most recent call last):
  File "/usr/src/homeassistant/homeassistant/helpers/update_coordinator.py", line 134, in _handle_refresh_interval
    await self._async_refresh(log_failures=True, scheduled=True)
  File "/usr/src/homeassistant/homeassistant/helpers/update_coordinator.py", line 265, in _async_refresh
    update_callback()
  File "/usr/src/homeassistant/homeassistant/helpers/entity.py", line 464, in async_write_ha_state
    self._async_write_ha_state()
  File "/usr/src/homeassistant/homeassistant/helpers/entity.py", line 505, in _async_write_ha_state
    extra_state_attributes = self.device_state_attributes
  File "/config/custom_components/grocy/entity.py", line 142, in device_state_attributes
    return json.loads(json.dumps(data, cls=GrocyJSONEncoder))
  File "/usr/local/lib/python3.9/json/__init__.py", line 234, in dumps
    return cls(
  File "/usr/local/lib/python3.9/json/encoder.py", line 199, in encode
    chunks = self.iterencode(o, _one_shot=True)
  File "/usr/local/lib/python3.9/json/encoder.py", line 257, in iterencode
    return _iterencode(o, 0)
  File "/config/custom_components/grocy/json_encode.py", line 26, in default
    return json.JSONEncoder.default(self, o)
  File "/usr/local/lib/python3.9/json/encoder.py", line 179, in default
    raise TypeError(f'Object of type {o.__class__.__name__} '
TypeError: Object of type ProductBarcodeData is not JSON serializable
2021-09-12 16:00:14 ERROR (SyncWorker_10) [homeassistant.util.yaml.loader] mapping values are not allowed here
  in "/config/integrations/../entities/climate/woonkamer.yaml", line 2, column 7
2021-09-12 16:00:17 ERROR (SyncWorker_1) [homeassistant.components.command_line] Command failed: /config/scripts/get_shopping_list.py
2021-09-12 16:00:17 WARNING (SyncWorker_1) [homeassistant.components.command_line.sensor] Empty reply found when expecting JSON data
2021-09-12 16:00:20 ERROR (MainThread) [homeassistant] Error doing job: Task exception was never retrieved
Traceback (most recent call last):
  File "/usr/src/homeassistant/homeassistant/helpers/update_coordinator.py", line 134, in _handle_refresh_interval
    await self._async_refresh(log_failures=True, scheduled=True)
  File "/usr/src/homeassistant/homeassistant/helpers/update_coordinator.py", line 265, in _async_refresh
    update_callback()
  File "/usr/src/homeassistant/homeassistant/helpers/entity.py", line 464, in async_write_ha_state
    self._async_write_ha_state()
  File "/usr/src/homeassistant/homeassistant/helpers/entity.py", line 505, in _async_write_ha_state
    extra_state_attributes = self.device_state_attributes
  File "/config/custom_components/grocy/entity.py", line 142, in device_state_attributes
    return json.loads(json.dumps(data, cls=GrocyJSONEncoder))
  File "/usr/local/lib/python3.9/json/__init__.py", line 234, in dumps
    return cls(
  File "/usr/local/lib/python3.9/json/encoder.py", line 199, in encode
    chunks = self.iterencode(o, _one_shot=True)
  File "/usr/local/lib/python3.9/json/encoder.py", line 257, in iterencode
    return _iterencode(o, 0)
  File "/config/custom_components/grocy/json_encode.py", line 26, in default
    return json.JSONEncoder.default(self, o)
  File "/usr/local/lib/python3.9/json/encoder.py", line 179, in default
    raise TypeError(f'Object of type {o.__class__.__name__} '
TypeError: Object of type ProductBarcodeData is not JSON serializable
2021-09-12 16:00:32 ERROR (MainThread) [homeassistant.helpers.template] Template variable error: list object has no element 6 when rendering '{{ state_attr('sensor.recipies', 'recepten')[states('input_number.recipe_id')|round].description.split('<li>')[6].split('<br />')[0]|replace('</li>','')}}'
2021-09-12 16:00:52 ERROR (MainThread) [homeassistant] Error doing job: Task exception was never retrieved
Traceback (most recent call last):
  File "/usr/src/homeassistant/homeassistant/helpers/update_coordinator.py", line 134, in _handle_refresh_interval
    await self._async_refresh(log_failures=True, scheduled=True)
  File "/usr/src/homeassistant/homeassistant/helpers/update_coordinator.py", line 265, in _async_refresh
    update_callback()
  File "/usr/src/homeassistant/homeassistant/helpers/entity.py", line 464, in async_write_ha_state
    self._async_write_ha_state()
  File "/usr/src/homeassistant/homeassistant/helpers/entity.py", line 505, in _async_write_ha_state
    extra_state_attributes = self.device_state_attributes
  File "/config/custom_components/grocy/entity.py", line 142, in device_state_attributes
    return json.loads(json.dumps(data, cls=GrocyJSONEncoder))
  File "/usr/local/lib/python3.9/json/__init__.py", line 234, in dumps
    return cls(
  File "/usr/local/lib/python3.9/json/encoder.py", line 199, in encode
    chunks = self.iterencode(o, _one_shot=True)
  File "/usr/local/lib/python3.9/json/encoder.py", line 257, in iterencode
    return _iterencode(o, 0)
  File "/config/custom_components/grocy/json_encode.py", line 26, in default
    return json.JSONEncoder.default(self, o)
  File "/usr/local/lib/python3.9/json/encoder.py", line 179, in default
    raise TypeError(f'Object of type {o.__class__.__name__} '
TypeError: Object of type ProductBarcodeData is not JSON serializable
2021-09-12 16:01:17 ERROR (SyncWorker_2) [homeassistant.components.command_line] Command failed: /config/scripts/get_shopping_list.py
2021-09-12 16:01:17 WARNING (SyncWorker_2) [homeassistant.components.command_line.sensor] Empty reply found when expecting JSON data
2021-09-12 16:01:25 ERROR (MainThread) [homeassistant] Error doing job: Task exception was never retrieved
Traceback (most recent call last):
  File "/usr/src/homeassistant/homeassistant/helpers/update_coordinator.py", line 134, in _handle_refresh_interval
    await self._async_refresh(log_failures=True, scheduled=True)
  File "/usr/src/homeassistant/homeassistant/helpers/update_coordinator.py", line 265, in _async_refresh
    update_callback()
  File "/usr/src/homeassistant/homeassistant/helpers/entity.py", line 464, in async_write_ha_state
    self._async_write_ha_state()
  File "/usr/src/homeassistant/homeassistant/helpers/entity.py", line 505, in _async_write_ha_state
    extra_state_attributes = self.device_state_attributes
  File "/config/custom_components/grocy/entity.py", line 142, in device_state_attributes
    return json.loads(json.dumps(data, cls=GrocyJSONEncoder))
  File "/usr/local/lib/python3.9/json/__init__.py", line 234, in dumps
    return cls(
  File "/usr/local/lib/python3.9/json/encoder.py", line 199, in encode
    chunks = self.iterencode(o, _one_shot=True)
  File "/usr/local/lib/python3.9/json/encoder.py", line 257, in iterencode
    return _iterencode(o, 0)
  File "/config/custom_components/grocy/json_encode.py", line 26, in default
    return json.JSONEncoder.default(self, o)
  File "/usr/local/lib/python3.9/json/encoder.py", line 179, in default
    raise TypeError(f'Object of type {o.__class__.__name__} '
TypeError: Object of type ProductBarcodeData is not JSON serializable
2021-09-12 16:01:32 ERROR (MainThread) [homeassistant.helpers.template] Template variable error: list object has no element 6 when rendering '{{ state_attr('sensor.recipies', 'recepten')[states('input_number.recipe_id')|round].description.split('<li>')[6].split('<br />')[0]|replace('</li>','')}}'
2021-09-12 16:01:57 ERROR (MainThread) [homeassistant] Error doing job: Task exception was never retrieved
Traceback (most recent call last):
  File "/usr/src/homeassistant/homeassistant/helpers/update_coordinator.py", line 134, in _handle_refresh_interval
    await self._async_refresh(log_failures=True, scheduled=True)
  File "/usr/src/homeassistant/homeassistant/helpers/update_coordinator.py", line 265, in _async_refresh
    update_callback()
  File "/usr/src/homeassistant/homeassistant/helpers/entity.py", line 464, in async_write_ha_state
    self._async_write_ha_state()
  File "/usr/src/homeassistant/homeassistant/helpers/entity.py", line 505, in _async_write_ha_state
    extra_state_attributes = self.device_state_attributes
  File "/config/custom_components/grocy/entity.py", line 142, in device_state_attributes
    return json.loads(json.dumps(data, cls=GrocyJSONEncoder))
  File "/usr/local/lib/python3.9/json/__init__.py", line 234, in dumps
    return cls(
  File "/usr/local/lib/python3.9/json/encoder.py", line 199, in encode
    chunks = self.iterencode(o, _one_shot=True)
  File "/usr/local/lib/python3.9/json/encoder.py", line 257, in iterencode
    return _iterencode(o, 0)
  File "/config/custom_components/grocy/json_encode.py", line 26, in default
    return json.JSONEncoder.default(self, o)
  File "/usr/local/lib/python3.9/json/encoder.py", line 179, in default
    raise TypeError(f'Object of type {o.__class__.__name__} '
TypeError: Object of type ProductBarcodeData is not JSON serializable
2021-09-12 16:02:17 ERROR (SyncWorker_2) [homeassistant.components.command_line] Command failed: /config/scripts/get_shopping_list.py
2021-09-12 16:02:17 WARNING (SyncWorker_2) [homeassistant.components.command_line.sensor] Empty reply found when expecting JSON data
2021-09-12 16:02:25 ERROR (SyncWorker_9) [homeassistant.util.yaml.loader] mapping values are not allowed here
  in "/config/integrations/../entities/climate/woonkamer.yaml", line 2, column 7
2021-09-12 16:02:29 ERROR (MainThread) [homeassistant] Error doing job: Task exception was never retrieved
Traceback (most recent call last):
  File "/usr/src/homeassistant/homeassistant/helpers/update_coordinator.py", line 134, in _handle_refresh_interval
    await self._async_refresh(log_failures=True, scheduled=True)
  File "/usr/src/homeassistant/homeassistant/helpers/update_coordinator.py", line 265, in _async_refresh
    update_callback()
  File "/usr/src/homeassistant/homeassistant/helpers/entity.py", line 464, in async_write_ha_state
    self._async_write_ha_state()
  File "/usr/src/homeassistant/homeassistant/helpers/entity.py", line 505, in _async_write_ha_state
    extra_state_attributes = self.device_state_attributes
  File "/config/custom_components/grocy/entity.py", line 142, in device_state_attributes
    return json.loads(json.dumps(data, cls=GrocyJSONEncoder))
  File "/usr/local/lib/python3.9/json/__init__.py", line 234, in dumps
    return cls(
  File "/usr/local/lib/python3.9/json/encoder.py", line 199, in encode
    chunks = self.iterencode(o, _one_shot=True)
  File "/usr/local/lib/python3.9/json/encoder.py", line 257, in iterencode
    return _iterencode(o, 0)
  File "/config/custom_components/grocy/json_encode.py", line 26, in default
    return json.JSONEncoder.default(self, o)
  File "/usr/local/lib/python3.9/json/encoder.py", line 179, in default
    raise TypeError(f'Object of type {o.__class__.__name__} '
TypeError: Object of type ProductBarcodeData is not JSON serializable
2021-09-12 16:02:32 ERROR (MainThread) [homeassistant.helpers.template] Template variable error: list object has no element 6 when rendering '{{ state_attr('sensor.recipies', 'recepten')[states('input_number.recipe_id')|round].description.split('<li>')[6].split('<br />')[0]|replace('</li>','')}}'
2021-09-12 16:03:02 ERROR (MainThread) [homeassistant] Error doing job: Task exception was never retrieved
Traceback (most recent call last):
  File "/usr/src/homeassistant/homeassistant/helpers/update_coordinator.py", line 134, in _handle_refresh_interval
    await self._async_refresh(log_failures=True, scheduled=True)
  File "/usr/src/homeassistant/homeassistant/helpers/update_coordinator.py", line 265, in _async_refresh
    update_callback()
  File "/usr/src/homeassistant/homeassistant/helpers/entity.py", line 464, in async_write_ha_state
    self._async_write_ha_state()
  File "/usr/src/homeassistant/homeassistant/helpers/entity.py", line 505, in _async_write_ha_state
    extra_state_attributes = self.device_state_attributes
  File "/config/custom_components/grocy/entity.py", line 142, in device_state_attributes
    return json.loads(json.dumps(data, cls=GrocyJSONEncoder))
  File "/usr/local/lib/python3.9/json/__init__.py", line 234, in dumps
    return cls(
  File "/usr/local/lib/python3.9/json/encoder.py", line 199, in encode
    chunks = self.iterencode(o, _one_shot=True)
  File "/usr/local/lib/python3.9/json/encoder.py", line 257, in iterencode
    return _iterencode(o, 0)
  File "/config/custom_components/grocy/json_encode.py", line 26, in default
    return json.JSONEncoder.default(self, o)
  File "/usr/local/lib/python3.9/json/encoder.py", line 179, in default
    raise TypeError(f'Object of type {o.__class__.__name__} '
TypeError: Object of type ProductBarcodeData is not JSON serializable
2021-09-12 16:03:17 ERROR (SyncWorker_8) [homeassistant.components.command_line] Command failed: /config/scripts/get_shopping_list.py
2021-09-12 16:03:17 WARNING (SyncWorker_8) [homeassistant.components.command_line.sensor] Empty reply found when expecting JSON data
2021-09-12 16:03:24 ERROR (MainThread) [homeassistant.components.github.sensor] GitHub error for esphome/esphome: Request exception for 'https://api.github.com/repos/esphome/esphome/pulls' with - 
2021-09-12 16:03:24 ERROR (MainThread) [homeassistant] Error doing job: unhandled exception during asyncio.run() shutdown
Traceback (most recent call last):
  File "/usr/local/lib/python3.9/site-packages/aiogithubapi/client.py", line 100, in async_call_api
    result = await self._session.request(**request_arguments)
  File "/usr/local/lib/python3.9/site-packages/aiohttp/client.py", line 544, in _request
    await resp.start(conn)
  File "/usr/local/lib/python3.9/site-packages/aiohttp/client_reqrep.py", line 890, in start
    message, payload = await self._protocol.read()  # type: ignore
  File "/usr/local/lib/python3.9/site-packages/aiohttp/streams.py", line 604, in read
    await self._waiter
asyncio.exceptions.CancelledError

The above exception was the direct cause of the following exception:

Traceback (most recent call last):
  File "/usr/src/homeassistant/homeassistant/components/github/sensor.py", line 240, in async_update
    await asyncio.gather(
  File "/usr/src/homeassistant/homeassistant/components/github/sensor.py", line 299, in _update_pulls
    results = await asyncio.gather(
  File "/usr/local/lib/python3.9/site-packages/aiogithubapi/namespaces/pulls.py", line 40, in list
    response = await self._client.async_call_api(
  File "/usr/local/lib/python3.9/site-packages/aiogithubapi/client.py", line 102, in async_call_api
    raise GitHubConnectionException(
aiogithubapi.exceptions.GitHubConnectionException: Request exception for 'https://api.github.com/repos/esphome/esphome/pulls' with - 
2021-09-12 16:03:24 ERROR (MainThread) [homeassistant] Error doing job: unhandled exception during asyncio.run() shutdown
Traceback (most recent call last):
  File "/usr/local/lib/python3.9/site-packages/aiogithubapi/client.py", line 100, in async_call_api
    result = await self._session.request(**request_arguments)
  File "/usr/local/lib/python3.9/site-packages/aiohttp/client.py", line 544, in _request
    await resp.start(conn)
  File "/usr/local/lib/python3.9/site-packages/aiohttp/client_reqrep.py", line 890, in start
    message, payload = await self._protocol.read()  # type: ignore
  File "/usr/local/lib/python3.9/site-packages/aiohttp/streams.py", line 604, in read
    await self._waiter
asyncio.exceptions.CancelledError

The above exception was the direct cause of the following exception:

Traceback (most recent call last):
  File "/usr/src/homeassistant/homeassistant/components/github/sensor.py", line 240, in async_update
    await asyncio.gather(
  File "/usr/src/homeassistant/homeassistant/components/github/sensor.py", line 299, in _update_pulls
    results = await asyncio.gather(
  File "/usr/local/lib/python3.9/site-packages/aiogithubapi/namespaces/pulls.py", line 40, in list
    response = await self._client.async_call_api(
  File "/usr/local/lib/python3.9/site-packages/aiogithubapi/client.py", line 102, in async_call_api
    raise GitHubConnectionException(
aiogithubapi.exceptions.GitHubConnectionException: Request exception for 'https://api.github.com/repos/esphome/esphome/pulls' with - 
2021-09-12 16:03:24 WARNING (Thread-105) [homeassistant.util.executor] Thread[SyncWorker_1] is still running at shutdown: File "/usr/local/lib/python3.9/threading.py", line 930, in _bootstrap
    self._bootstrap_inner()
  File "/usr/local/lib/python3.9/threading.py", line 973, in _bootstrap_inner
    self.run()
  File "/usr/local/lib/python3.9/threading.py", line 910, in run
    self._target(*self._args, **self._kwargs)
  File "/usr/local/lib/python3.9/concurrent/futures/thread.py", line 77, in _worker
    work_item.run()
  File "/usr/local/lib/python3.9/concurrent/futures/thread.py", line 52, in run
    result = self.fn(*self.args, **self.kwargs)
  File "/usr/src/homeassistant/homeassistant/components/command_line/sensor.py", line 103, in update
    self.data.update()
  File "/usr/src/homeassistant/homeassistant/components/command_line/sensor.py", line 174, in update
    self.value = check_output_or_log(command, self.timeout)
  File "/usr/src/homeassistant/homeassistant/components/command_line/__init__.py", line 36, in check_output_or_log
    return_value = subprocess.check_output(
  File "/usr/local/lib/python3.9/subprocess.py", line 424, in check_output
    return run(*popenargs, stdout=PIPE, timeout=timeout, check=True,
  File "/usr/local/lib/python3.9/subprocess.py", line 507, in run
    stdout, stderr = process.communicate(input, timeout=timeout)
  File "/usr/local/lib/python3.9/subprocess.py", line 1134, in communicate
    stdout, stderr = self._communicate(input, endtime, timeout)
  File "/usr/local/lib/python3.9/subprocess.py", line 1979, in _communicate
    ready = selector.select(timeout)
  File "/usr/local/lib/python3.9/selectors.py", line 416, in select
    fd_event_list = self._selector.poll(timeout)
2021-09-12 16:03:25 WARNING (Thread-105) [homeassistant.util.executor] Thread[SyncWorker_1] is still running at shutdown: File "/usr/local/lib/python3.9/threading.py", line 930, in _bootstrap
    self._bootstrap_inner()
  File "/usr/local/lib/python3.9/threading.py", line 973, in _bootstrap_inner
    self.run()
  File "/usr/local/lib/python3.9/threading.py", line 910, in run
    self._target(*self._args, **self._kwargs)
  File "/usr/local/lib/python3.9/concurrent/futures/thread.py", line 77, in _worker
    work_item.run()
  File "/usr/local/lib/python3.9/concurrent/futures/thread.py", line 52, in run
    result = self.fn(*self.args, **self.kwargs)
  File "/usr/src/homeassistant/homeassistant/components/command_line/sensor.py", line 103, in update
    self.data.update()
  File "/usr/src/homeassistant/homeassistant/components/command_line/sensor.py", line 174, in update
    self.value = check_output_or_log(command, self.timeout)
  File "/usr/src/homeassistant/homeassistant/components/command_line/__init__.py", line 36, in check_output_or_log
    return_value = subprocess.check_output(
  File "/usr/local/lib/python3.9/subprocess.py", line 424, in check_output
    return run(*popenargs, stdout=PIPE, timeout=timeout, check=True,
  File "/usr/local/lib/python3.9/subprocess.py", line 507, in run
    stdout, stderr = process.communicate(input, timeout=timeout)
  File "/usr/local/lib/python3.9/subprocess.py", line 1134, in communicate
    stdout, stderr = self._communicate(input, endtime, timeout)
  File "/usr/local/lib/python3.9/subprocess.py", line 1979, in _communicate
    ready = selector.select(timeout)
  File "/usr/local/lib/python3.9/selectors.py", line 416, in select
    fd_event_list = self._selector.poll(timeout)
2021-09-12 16:03:26 ERROR (MainThread) [homeassistant] Error doing job: Future exception was never retrieved
Traceback (most recent call last):
  File "/usr/local/lib/python3.9/concurrent/futures/thread.py", line 52, in run
    result = self.fn(*self.args, **self.kwargs)
  File "/usr/src/homeassistant/homeassistant/components/command_line/sensor.py", line 103, in update
    self.data.update()
  File "/usr/src/homeassistant/homeassistant/components/command_line/sensor.py", line 174, in update
    self.value = check_output_or_log(command, self.timeout)
  File "/usr/src/homeassistant/homeassistant/components/command_line/__init__.py", line 36, in check_output_or_log
    return_value = subprocess.check_output(
  File "/usr/local/lib/python3.9/subprocess.py", line 424, in check_output
    return run(*popenargs, stdout=PIPE, timeout=timeout, check=True,
  File "/usr/local/lib/python3.9/subprocess.py", line 507, in run
    stdout, stderr = process.communicate(input, timeout=timeout)
  File "/usr/local/lib/python3.9/subprocess.py", line 1134, in communicate
    stdout, stderr = self._communicate(input, endtime, timeout)
  File "/usr/local/lib/python3.9/subprocess.py", line 1979, in _communicate
    ready = selector.select(timeout)
  File "/usr/local/lib/python3.9/selectors.py", line 416, in select
    fd_event_list = self._selector.poll(timeout)
SystemExit
